{"result":{"history_size":2,"folders":["pa3"],"nr":487,"data":{"embed_links":[]},"created":"2024-11-16T23:22:06Z","bucket_order":3,"no_answer_followup":1,"change_log":[{"anon":"no","uid":"l86a6jsdusz6lo","data":"m3ksls6vl1u7l6","v":"all","type":"create","when":"2024-11-16T23:22:06Z"},{"anon":"no","uid":"l86a6jsdusz6lo","data":"m3ksm8lkw6iu","v":"all","type":"update","when":"2024-11-16T23:22:27Z"},{"anon":"no","uid":"lmr7yhnqdjb6ul","data":"m3kt7zlq8nb1t5","to":"m3ksls6ojz57l5","type":"i_answer","when":"2024-11-16T23:39:22Z"},{"anon":"no","uid":"l86a6jsdusz6lo","to":"m3ksls6ojz57l5","type":"followup","when":"2024-11-17T23:10:55Z","cid":"m3m7n9eca02lw"},{"anon":"no","uid":"l86a6jsdusz6lo","to":"m3ksls6ojz57l5","type":"feedback","when":"2024-11-18T01:58:40Z","cid":"m3mdmzrwhe770h"},{"anon":"no","uid":"lmr7yhnqdjb6ul","to":"m3ksls6ojz57l5","type":"feedback","when":"2024-11-18T02:10:22Z","cid":"m3me21ev9kn182"},{"anon":"no","uid":"l86a6jsdusz6lo","to":"m3ksls6ojz57l5","type":"feedback","when":"2024-11-18T07:58:06Z","cid":"m3mqh8agdns264"},{"anon":"no","uid":"lmr7yhnqdjb6ul","to":"m3ksls6ojz57l5","type":"feedback","when":"2024-11-18T08:27:46Z","cid":"m3mrjd5ebr26uk"},{"anon":"no","uid":"l86a6jsdusz6lo","to":"m3ksls6ojz57l5","type":"feedback","when":"2024-11-19T00:48:29Z","cid":"m3nqkkvezn77ab"}],"bucket_name":"Today","history":[{"anon":"no","uid":"l86a6jsdusz6lo","subject":"Problem with opening Jupyter Notebook in virtual environment for PA3","created":"2024-11-16T23:22:27Z","content":"<p>Hi,</p>\n<p></p>\n<p>Until now, I have been using the same Conda virtual environment on WSL for the assignments in this class. However, when I run <kbd>juypter notebook</kbd> in my Conda environment, it gives the following errors:</p>\n<p></p>\n<pre>\nTraceback (most recent call last):\n  File &#34;/home/eric/anaconda3/lib/python3.12/site-packages/jupyter_server/services/sessions/sessionmanager.py&#34;, line 14, in &lt;module&gt;\n    import sqlite3\n  File &#34;/home/eric/anaconda3/lib/python3.12/sqlite3/__init__.py&#34;, line 57, in &lt;module&gt;\n    from sqlite3.dbapi2 import *\n  File &#34;/home/eric/anaconda3/lib/python3.12/sqlite3/dbapi2.py&#34;, line 27, in &lt;module&gt;\n    from _sqlite3 import *\nImportError: /home/eric/anaconda3/lib/python3.12/lib-dynload/_sqlite3.cpython-312-x86_64-linux-gnu.so: undefined symbol: sqlite3_deserialize\n\nDuring handling of the above exception, another exception occurred:\n\nTraceback (most recent call last):\n  File &#34;/home/eric/anaconda3/bin/jupyter-notebook&#34;, line 7, in &lt;module&gt;\n    from notebook.app import main\n  File &#34;/home/eric/anaconda3/lib/python3.12/site-packages/notebook/app.py&#34;, line 17, in &lt;module&gt;\n    from jupyter_server.serverapp import flags\n  File &#34;/home/eric/anaconda3/lib/python3.12/site-packages/jupyter_server/serverapp.py&#34;, line 107, in &lt;module&gt;\n    from jupyter_server.gateway.managers import (\n  File &#34;/home/eric/anaconda3/lib/python3.12/site-packages/jupyter_server/gateway/managers.py&#34;, line 32, in &lt;module&gt;\n    from ..services.sessions.sessionmanager import SessionManager\n  File &#34;/home/eric/anaconda3/lib/python3.12/site-packages/jupyter_server/services/sessions/sessionmanager.py&#34;, line 17, in &lt;module&gt;\n    from pysqlite2 import dbapi2 as sqlite3  # type:ignore[no-redef]\n    ^^^^^^^^^^^^^^^^^^^^^^^^^^^^^^^^^^^^^^^\nModuleNotFoundError: No module named &#39;pysqlite2&#39;</pre>\n<p></p>\n<p>I find this really disturbing, because the <kbd>jupyter notebook</kbd> command worked fine yesterday. The only thing I changed was to install certain libraries using Conda to try to fix errors in the notebook, but now the notebook can&#39;t open at all anymore.</p>\n<p></p>\n<p>The commands I used to install things were:</p>\n<p><kbd>pip install google-colab<br />conda install -c conda-forge google-colab<br />brew upgrade google-cloud-sdk<br />conda install imp</kbd></p>\n<p></p>\n<p>What can I do to make the Jupyter Notebook work again?</p>"},{"anon":"no","uid":"l86a6jsdusz6lo","subject":"Problem with starting virtual environment for PA3","created":"2024-11-16T23:22:06Z","content":"<p>Hi,</p>\n<p></p>\n<p>Until now, I have been using the same Conda virtual environment on WSL for the assignments in this class. However, when I run <kbd>juypter notebook</kbd> in my Conda environment, it gives the following errors:</p>\n<p></p>\n<pre>\nTraceback (most recent call last):\n  File &#34;/home/eric/anaconda3/lib/python3.12/site-packages/jupyter_server/services/sessions/sessionmanager.py&#34;, line 14, in &lt;module&gt;\n    import sqlite3\n  File &#34;/home/eric/anaconda3/lib/python3.12/sqlite3/__init__.py&#34;, line 57, in &lt;module&gt;\n    from sqlite3.dbapi2 import *\n  File &#34;/home/eric/anaconda3/lib/python3.12/sqlite3/dbapi2.py&#34;, line 27, in &lt;module&gt;\n    from _sqlite3 import *\nImportError: /home/eric/anaconda3/lib/python3.12/lib-dynload/_sqlite3.cpython-312-x86_64-linux-gnu.so: undefined symbol: sqlite3_deserialize\n\nDuring handling of the above exception, another exception occurred:\n\nTraceback (most recent call last):\n  File &#34;/home/eric/anaconda3/bin/jupyter-notebook&#34;, line 7, in &lt;module&gt;\n    from notebook.app import main\n  File &#34;/home/eric/anaconda3/lib/python3.12/site-packages/notebook/app.py&#34;, line 17, in &lt;module&gt;\n    from jupyter_server.serverapp import flags\n  File &#34;/home/eric/anaconda3/lib/python3.12/site-packages/jupyter_server/serverapp.py&#34;, line 107, in &lt;module&gt;\n    from jupyter_server.gateway.managers import (\n  File &#34;/home/eric/anaconda3/lib/python3.12/site-packages/jupyter_server/gateway/managers.py&#34;, line 32, in &lt;module&gt;\n    from ..services.sessions.sessionmanager import SessionManager\n  File &#34;/home/eric/anaconda3/lib/python3.12/site-packages/jupyter_server/services/sessions/sessionmanager.py&#34;, line 17, in &lt;module&gt;\n    from pysqlite2 import dbapi2 as sqlite3  # type:ignore[no-redef]\n    ^^^^^^^^^^^^^^^^^^^^^^^^^^^^^^^^^^^^^^^\nModuleNotFoundError: No module named &#39;pysqlite2&#39;</pre>\n<p></p>\n<p>I find this really disturbing, because the <kbd>jupyter notebook</kbd> command worked fine yesterday. The only thing I changed was to install certain libraries using Conda to try to fix errors in the notebook, but now the notebook can&#39;t open at all anymore.</p>\n<p></p>\n<p>The commands I used to install things were:</p>\n<p><kbd>pip install google-colab<br />conda install -c conda-forge google-colab<br />brew upgrade google-cloud-sdk<br />conda install imp</kbd></p>\n<p></p>\n<p>What can I do to make the Jupyter Notebook work again?</p>"}],"type":"question","tags":["pa3","student"],"tag_good":[],"unique_views":111,"children":[{"history_size":1,"folders":[],"data":{"embed_links":[]},"created":"2024-11-16T23:39:22Z","bucket_order":3,"tag_endorse":[],"bucket_name":"Today","history":[{"anon":"no","uid":"lmr7yhnqdjb6ul","subject":"","created":"2024-11-16T23:39:22Z","content":"<p>I recommend using the browser to access Google Colab instead.</p>\n<p></p>\n<p>To be honest, I haven&#39;t seen the command &#34;pip install google-colab&#34; before. So, sorry I cannot help you out on this. There are probably some library version conflicts in your current environment, so the jupyter notebook is not working.</p>"}],"type":"i_answer","tag_endorse_arr":[],"children":[],"id":"m3kt7zlko261t4","config":{"editor":"rte"},"is_tag_endorse":false},{"anon":"no","folders":[],"data":{"embed_links":null},"no_upvotes":0,"subject":"<p>I think installing google-colab with Pip was the wrong way to go, and I should have installed it with Conda instead. But it&#39;s even worse now.  I can&#39;t even get into the Conda environment that I used for the previous assignments anymore.</p>\n<p></p>\n<p>Here is the error I get:</p>\n<p></p>\n<pre>\neric@DESKTOP-K013VFU:~/homework/cse256/cse256_hw3$ eval &#34;$(/home/eric/anaconda3/bin/conda shell.bash hook)&#34;\nError while loading conda entry point: conda-libmamba-solver (libarchive.so.20: cannot open shared object file: No such file or directory)\nError while loading conda entry point: conda-libmamba-solver (libarchive.so.20: cannot open shared object file: No such file or directory)\n\nEnvironmentNameNotFound: Could not find conda environment: baseev\nYou can list all discoverable environments with `conda info --envs`.</pre>\n<p></p>\n<p>I&#39;ll try accessing the Google Colab via a browser and let you know how that goes.</p>","created":"2024-11-17T23:10:55Z","bucket_order":3,"bucket_name":"Today","type":"followup","tag_good":[],"uid":"l86a6jsdusz6lo","children":[{"anon":"no","folders":[],"data":{"embed_links":null},"subject":"<p>So far, the Google Colab solution seems to be working alright. Thanks!</p>\n<p></p>\n<p>However, it is annoying that I have to run the pieces of code from the beginning every time the page reloads or times out. I also have to go through the same agreement to let Google Colab view my Google docs. Is there any way to make it so that the state of the program is saved?</p>","created":"2024-11-18T01:58:40Z","bucket_order":4,"bucket_name":"Yesterday","type":"feedback","tag_good":[],"uid":"l86a6jsdusz6lo","children":[],"tag_good_arr":[],"id":"m3mdmzrwhe770h","d-bucket":"Yesterday","updated":"2024-11-18T01:58:40Z","config":{"editor":"rte"}},{"anon":"no","folders":[],"data":{"embed_links":null},"subject":"There is a way, but paid... Upgrade to Colab Pro&#43;. But I don&#39;t recommend it unless you really need computing resources, haha.","created":"2024-11-18T02:10:22Z","bucket_order":4,"bucket_name":"Yesterday","type":"feedback","tag_good":[],"uid":"lmr7yhnqdjb6ul","children":[],"tag_good_arr":[],"id":"m3me21ev9kn182","d-bucket":"Yesterday","updated":"2024-11-18T02:10:22Z","config":{"editor":"rte"}},{"anon":"no","folders":[],"data":{"embed_links":null},"subject":"So it&#39;s normal to have to go through everything, including the same agreement, every time you run the code from the Jupyter notebook? This is inconvenient for me because running all the code up to the point I left off at sometimes takes several minutes.","created":"2024-11-18T07:58:06Z","bucket_order":4,"bucket_name":"Yesterday","type":"feedback","tag_good":[],"uid":"l86a6jsdusz6lo","children":[],"tag_good_arr":[],"id":"m3mqh8agdns264","d-bucket":"Yesterday","updated":"2024-11-18T07:58:06Z","config":{"editor":"rte"}},{"anon":"no","folders":[],"data":{"embed_links":null},"subject":"yes, same case for me","created":"2024-11-18T08:27:46Z","bucket_order":4,"bucket_name":"Yesterday","type":"feedback","tag_good":[],"uid":"lmr7yhnqdjb6ul","children":[],"tag_good_arr":[],"id":"m3mrjd5ebr26uk","d-bucket":"Yesterday","updated":"2024-11-18T08:27:46Z","config":{}},{"anon":"no","folders":[],"data":{"embed_links":null},"subject":"<p>Can I request an extension on this assignment? Only now, a few hours before the due date, do I actually understand the assignment well enough to start doing it.</p>\n<p></p>\n<p>I finally got through all the document database building up to the &#34;5 TODO&#34; section.</p>","created":"2024-11-19T00:48:29Z","bucket_order":3,"bucket_name":"Today","type":"feedback","tag_good":[],"uid":"l86a6jsdusz6lo","children":[],"tag_good_arr":[],"id":"m3nqkkvezn77ab","updated":"2024-11-19T00:48:59Z","config":{"editor":"rte"}}],"tag_good_arr":[],"no_answer":1,"id":"m3m7n9eca02lw","updated":"2024-11-19T00:48:29Z","config":{"editor":"rte"}}],"tag_good_arr":[],"no_answer":0,"id":"m3ksls6ojz57l5","config":{"editor":"rte","has_emails_sent":1},"status":"active","drafts":{},"request_instructor":0,"request_instructor_me":false,"bookmarked":2,"num_favorites":0,"my_favorite":false,"is_bookmarked":false,"is_tag_good":false,"q_edits":[],"i_edits":[],"s_edits":[],"t":1731990479625,"default_anonymity":"no"},"error":null,"aid":"m3nyev3xh9y5qu"}